# 1.警告

```
fw <- function() {
  cat("1\n")
  warning("W1")
  cat("2\n")
  warning("W2")
  cat("3\n")
  warning("W3")
}

fw()
#> 1
#> 2
#> 3
#> Warning messages:
#> 1: In f() : W1
#> 2: In f() : W2
#> 3: In f() : W3
```

**可以通过设置 [options(warn = 1)](https://rdrr.io/r/base/options.html) 来设置警告的消息立即发生**

**要将警告变为错误，请设置 [options(warn = 2)](https://rdrr.io/r/base/options.html) ，可以立即看出错误在哪**

**恢复警告options(warn = 0) **

# 2.错误

```
f <- function() g()
g <- function() h()
h <- function() stop("This is an error!")

f()
#> Error in h(): This is an error!

h <- function() stop("This is an error!", call. = FALSE)
f()
#> Error: This is an error!
```

**通常使用call. = FALSE来不显示调用的函数名**

# 3.隐藏error和warning

**1.error出现之后继续运行**

```
f1 <- function(x) {
  log(x)
  10
}
f1("x")
#> Error in log(x): non-numeric argument to mathematical function

f2 <- function(x) {
  try(log(x))
  10
}
f2("a")
#> Error in log(x) : non-numeric argument to mathematical function
#> [1] 10

# 但是作者不推荐使用try
```

**2.不显示警告和信息**

```
suppressWarnings({
  warning("Uhoh!")
  warning("Another warning")
  1
})
#> [1] 1

suppressMessages({
  message("Hello there")
  2
})
#> [1] 2

suppressWarnings({
  message("You can still see me")
  3
})
#> You can still see me
#> [1] 3
```

# 4.代码退出执行

```
f3 <- function(x) {
  tryCatch(
    error = function(cnd) NA,
    log(x)
  )
}

f3("x")
#> [1] NA
# 这里是捕捉到error了，所以就返回了NA

tryCatch(
  error = function(cnd) 10,
  1 + 1
)
#> [1] 2

tryCatch(
  error = function(cnd) 10,
  {
    message("Hi!")
    1 + 1
  }
)
#> Hi!
#> [1] 2

# 如果捕捉的条件对象的类或者类型不符合tryCatch捕捉的类型，那么代码会正常执行

tryCatch(
  message = function(cnd) "There",
  {
    message("Here")
    stop("This code is never run!")
  }
)
#> [1] "There"
# 中括号里面的是要执行的代码
```

```
path <- tempfile()
tryCatch(
  {
    writeLines("Hi!", path)
    # ...
  },
  finally = {
    # always run
    unlink(path)
  }
)
# finally可以控制程序退出时执行一些操作，类似于on.exit()
```

# 5.调用处理程序

```
tryCatch(
  message = function(cnd) cat("Caught a message!\n"), 
  {
    message("Someone there?")
    message("Why, yes!")
  }
)
#> Caught a message!

# tryCatch捕捉后会自动退出程序

withCallingHandlers(
  message = function(cnd) cat("Caught a message!\n"), 
  {
    message("Someone there?")
    message("Why, yes!")
  }
)
#> Caught a message!
#> Someone there?
#> Caught a message!
#> Why, yes!

# withCallingHandlers捕捉后会继续执行继续捕捉

# tryCatch和withCallingHandlers对比，withCallingHandlers当遇到message的时候就会打印Caught a message!，所以打印了两次(因为并没有像tryCatch一样退出程序)
```

# 6.自定义错误提示

```
tryCatch(
  error_bad_argument = function(cnd) "bad_argument",
  error = function(cnd) "other error",
  my_log("a")
)
#> [1] "bad_argument"

# 因为my_log(a)返回的error的类是error_bad_argument，所以报错是bad_argument
```

# 7.有错误时返回错误，无错误返回正确结果

```
does_error <- function(expr) {
  tryCatch(
    error = function(cnd) TRUE,
    {
      expr
      FALSE
    }
  )
}
# 捕捉错误
does_error(log("X"))
# TRUE
does_error(log(10))
# FALSE
```

# 8.将正确结果和错误结果一起呈现

```
safety <- function(expr) {
  tryCatch(
    error = function(cnd) {
      list(result = NULL, error = cnd)
    },
    list(result = expr, error = NULL)
  )
}

str(safety(1 + 10))
#> List of 2
#>  $ result: num 11
#>  $ error : NULL
str(safety(stop("Error!")))
#> List of 2
#>  $ result: NULL
#>  $ error :List of 2
#>   ..$ message: chr "Error!"
#>   ..$ call   : language doTryCatch(return(expr), name, parentenv, handler)
#>   ..- attr(*, "class")= chr [1:3] "simpleError" "error" "condition"
```

# 9.提示是哪个参数报错

```
log(letters)
#> Error in log(letters): non-numeric argument to mathematical function
log(1:10, base = letters)
#> Error in log(1:10, base = letters): non-numeric argument to mathematical
#> function

# 像base包的提示方法就无法知道
```

```
my_log <- function(x, base = exp(1)) {
  if (!is.numeric(x)) {
    abort(paste0(
      "`x` must be a numeric vector; not ", typeof(x), "."
    ))
  }
  if (!is.numeric(base)) {
    abort(paste0(
      "`base` must be a numeric vector; not ", typeof(base), "."
    ))
  }

  base::log(x, base = base)
}
# 可以提示哪个参数出错了
```

# 10.rlang的abort函数

```
abort_bad_argument <- function(arg, must, not = NULL) {
  msg <- glue::glue("`{arg}` must {must}")
  if (!is.null(not)) {
    not <- typeof(not)
    msg <- glue::glue("{msg}; not {not}.")
  }
  
  abort(class = "error_bad_argument", 
        message = msg, 
        arg = arg, 
        must = must, 
        not = not
  )
}
# 可以抛出错误的类
```

# 11.自定义一个抛出自定义异常的函数

**为什么我们要用自定义的异常**

**因为您随后可以使用 tryCatch() 捕获特定类型的错误，而不是依赖于错误字符串的比较，这是有风险的，尤其是在翻译消息时.**

```
stop_custom <- function(.subclass, message, call = NULL, ...) {
  err <- structure(
    list(
      message = message,
      call = call,
      ...
    ),
    class = c(.subclass, "error", "condition")
  )
  stop(err)
}

err <- catch_cnd(
  stop_custom("error_new", "This is a custom error", x = 10)
)
class(err)
err$x

# structure是创建一个S3对象
# stop函数会使用这个类里面的message信息进行提示
```

# 12.注意提示错误的摆放位置

```
abort_bad_argument <- function(arg, must, not = NULL) {
  msg <- glue::glue("`{arg}` must {must}")
  if (!is.null(not)) {
    not <- typeof(not)
    msg <- glue::glue("{msg}; not {not}.")
  }
  
  abort("error_bad_argument", 
        message = msg, 
        arg = arg, 
        must = must, 
        not = not
  )
}

my_log <- function(x, base = exp(1)) {
  if (!is.numeric(x)) {
    abort_bad_argument("x", must = "be numeric", not = x)
  }
  if (!is.numeric(base)) {
    abort_bad_argument("base", must = "be numeric", not = base)
  }
  
  base::log(x, base = base)
}

my_log(x = letters , base = 10)



tryCatch(
  error_bad_argument = function(cnd) "bad_argument",
  error = function(cnd) "other error",
  my_log("a")
)
#> [1] "bad_argument"


tryCatch(
  error = function(cnd) "other error",
  error_bad_argument = function(cnd) "bad_argument",
  my_log(1:10 , base = "Fea")
)
#> [1] "other error"
# 但是我们想要的是bad_argument，所以需要摆放好位置

# 因为检测到error，可能是判断到类的父类是error，所以没有向下执行
# 所以正确的应该是

tryCatch(
  error_bad_argument = function(cnd) "bad_argument",
  error = function(cnd) "other error",
  my_log(1:10 , base = "Fea")
)
#> [1] "bad_argument"
# 摆到前面
```

# 13.rlang包的catch_cnd是如何把错误的信息抓住的

```
catch_cnd <- function(expr) {
  tryCatch(
    condition = function(cnd) cnd, 
    {
      expr
      NULL
    }
  )
}
# 是通过tryCatch函数来捕捉到这个错误，并且以S3类的方式呈现出来
```

# 14.如何使得出现错误但是不显示出来

```
suppressErrors <- function(expr) {
  tryCatch(
    error = function(cnd) invisible(cnd),
    interrupt = function(cnd) {
      stop("Terminated by the user.",
        call. = FALSE
      )
    },
    expr
  )
}
# 可以使得出现error不提示
```

```
suppresscondition <- function(expr){
  tryCatch(
    condition = function(cnd) invisible(cnd)
  ,
  expr)
}
# 可以使得出现任何信号都不提示
```

